<?xml version="1.0" encoding="utf-8"?>
<robot name="piper_link3_gripper">
  <link name="link3">
    <inertial>
      <origin xyz="-0.0996835215213704 0.0349477226691318 0.000508025815507312" rpy="0 0 0"/>
      <mass value="0.290847697793211"/>
      <inertia ixx="0.000107879011637167" ixy="2.92669521203626E-05" ixz="6.825922326238E-07" iyy="0.000214751671792086" iyz="-7.78469047878196E-07" izz="0.000241923439340319"/>
    </inertial>
    <visual>
      <origin xyz="0 0 0" rpy="0 0 0"/>
      <geometry>
        <mesh filename="../meshes/dark_dae/link3.obj"/>
      </geometry>
    </visual>
    <collision>
      <origin xyz="0 0 0" rpy="0 0 0"/>
      <geometry>
        <box size="0.30 0.08 0.08"/>
      </geometry>
    </collision>
  </link>

  <link name="link4">
    <inertial>
      <origin xyz="0.000276464622387979 -0.00102803669324875 -0.00472830700561663" rpy="0 0 0"/>
      <mass value="0.127087348341362"/>
      <inertia ixx="3.82011730423416E-05" ixy="-4.92358350897513E-08" ixz="4.89589432973119E-08" iyy="4.87048555222578E-05" iyz="6.70802942500512E-08" izz="4.10592077565559E-05"/>
    </inertial>
    <visual>
      <origin xyz="0 0 0" rpy="0 0 0"/>
      <geometry>
        <mesh filename="../meshes/dark_dae/link4.obj"/>
      </geometry>
    </visual>
    <collision>
      <origin xyz="0 0 0" rpy="0 0 0"/>
      <geometry>
        <box size="0.20 0.08 0.08"/>
      </geometry>
    </collision>
  </link>
  <joint name="joint4" type="revolute">
    <origin xyz="-0.24221 0.068514 0" rpy="-1.5708 0 1.3826"/>
    <parent link="link3"/>
    <child link="link4"/>
    <axis xyz="0 0 1"/>
    <limit lower="-3.14159" upper="3.14159" effort="100" velocity="3"/>
  </joint>

  <link name="link5">
    <inertial>
      <origin xyz="8.82262433516967E-05 0.0566829014808256 -0.00196119720482461" rpy="0 0 0"/>
      <mass value="0.144711242639457"/>
      <inertia ixx="4.39644313662493E-05" ixy="-3.59259686444846E-08" ixz="-1.89747741386183E-08" iyy="5.63173920951307E-05" iyz="-2.1540716689785E-07" izz="4.88713664675268E-05"/>
    </inertial>
    <visual>
      <origin xyz="0 0 0" rpy="0 0 -3.14"/>
      <geometry>
        <mesh filename="../meshes/dark_dae/link5.obj"/>
      </geometry>
    </visual>
    <collision>
      <origin xyz="0 0 0" rpy="0 0 -3.14"/>
      <geometry>
        <box size="0.14 0.10 0.06"/>
      </geometry>
    </collision>
  </link>
  <joint name="joint5" type="revolute">
    <origin xyz="0 0 0" rpy="1.5708 0 0"/>
    <parent link="link4"/>
    <child link="link5"/>
    <axis xyz="0 0 1"/>
    <limit lower="-3.14159" upper="3.14159" effort="100" velocity="3"/>
  </joint>

  <link name="link6">
    <inertial>
      <origin xyz="0.00103120214523473 0.0121761387587524 0.0315480874960164" rpy="0 0 0"/>
      <mass value="0.195187143240719"/>
      <inertia ixx="6.43790256535539E-05" ixy="-1.2366166157046E-06" ixz="1.97664606328472E-07" iyy="0.000126146396374301" iyz="2.41157078516408E-06" izz="0.000154087076816444"/>
    </inertial>
    <visual>
      <origin xyz="0 0 0" rpy="0 0 0"/>
      <geometry>
        <mesh filename="../meshes/dark_dae/link6_.obj"/>
      </geometry>
    </visual>
    <collision>
      <origin xyz="0 0 0" rpy="0 0 0"/>
      <geometry>
        <box size="0.08 0.08 0.18"/>
      </geometry>
    </collision>
  </link>
  <joint name="joint6" type="revolute">
    <origin xyz="0 0.091 0.0014165" rpy="-1.5708 -1.5708 0"/>
    <parent link="link5"/>
    <child link="link6"/>
    <axis xyz="0 0 1"/>
    <limit lower="-3.14159" upper="3.14159" effort="100" velocity="3"/>
  </joint>

  <link name="tcp">
    <inertial>
      <origin xyz="0 0 0" rpy="0 0 0"/>
      <mass value="0.001"/>
      <inertia ixx="1e-6" ixy="0" ixz="0" iyy="1e-6" iyz="0" izz="1e-6"/>
    </inertial>
  </link>
  <joint name="tcp_joint" type="fixed">
    <origin xyz="0 0 0.14" rpy="0 0 0"/>
    <parent link="link6"/>
    <child link="tcp"/>
  </joint>

  <link name="camera_stand">
    <inertial>
      <origin xyz="0.00103120214523473 0.0121761387587524 0.0315480874960164" rpy="0 0 0"/>
      <mass value="0.195187143240719"/>
      <inertia ixx="6.43790256535539E-05" ixy="-1.2366166157046E-06" ixz="1.97664606328472E-07" iyy="0.000126146396374301" iyz="2.41157078516408E-06" izz="0.000154087076816444"/>
    </inertial>
    <visual>
      <origin xyz="-0.0025 0 0" rpy="0 0 0"/>
      <geometry>
        <mesh filename="../meshes/dark_dae/d435_camera_stand.obj"/>
      </geometry>
    </visual>
    <collision>
      <origin xyz="0 0 0" rpy="0 0 0"/>
      <geometry>
        <box size="0.04 0.03 0.10"/>
      </geometry>
    </collision>
  </link>
  <joint name="camera_stand_joint" type="fixed">
    <origin xyz="0.0 0.013 0.03" rpy="0 0 0"/>
    <parent link="link6"/>
    <child link="camera_stand"/>
  </joint>

  <link name="d435_camera_link"/>
  <joint name="camera_joint" type="fixed">
    <origin xyz="0 0 0" rpy="0 0 0"/>
    <parent link="d435_camera_link"/>
    <child link="camera_bottom_screw_frame"/>
  </joint>

  <link name="camera_bottom_screw_frame"/>
  <joint name="camera_link_joint" type="fixed">
    <origin xyz="0.010600000000000002 0.0175 0.0125" rpy="0 0 0"/>
    <parent link="camera_bottom_screw_frame"/>
    <child link="camera_link"/>
  </joint>

  <link name="camera_link">
    <visual>
      <origin xyz="0.0043 0.0 0" rpy="0.0 0.0 0.0"/>
      <geometry>
        <mesh filename="../../realsense2_description/meshes/d435.obj"/>
      </geometry>
    </visual>
    <collision>
      <origin xyz="0 -0.0175 0" rpy="0 0 0"/>
      <geometry>
        <box size="0.02505 0.09 0.025"/>
      </geometry>
    </collision>
    <inertial>
      <mass value="0.072"/>
      <origin xyz="0 0 0"/>
      <inertia ixx="0.0003881243" ixy="0.0" ixz="0.0" iyy="0.0000498940" iyz="0.0" izz="0.0003879257"/>
    </inertial>
  </link>
  <joint name="d435_camera_joint" type="fixed">
    <origin xyz="-0.045 0.042 -0.004" rpy="0.52 0.0 0.0"/>
    <parent link="camera_stand"/>
    <child link="d435_camera_link"/>
  </joint>

  <link name="link7">
    <inertial>
      <origin xyz="-0.000277778383727112 -0.0467673043650824 -0.00921029491873201" rpy="0 0 0"/>
      <mass value="0.02648229234527"/>
      <inertia ixx="9.99787479924589E-06" ixy="-1.57548495096104E-07" ixz="-2.71342775003487E-08" iyy="6.1795212293655E-06" iyz="-1.58939803580081E-06" izz="1.42102717246564E-05"/>
    </inertial>
    <visual>
      <origin xyz="0 0 0" rpy="0 0 0"/>
      <geometry>
        <mesh filename="../meshes/dark_dae/link7.obj"/>
      </geometry>
      <material name="link7_color">
        <color rgba="0.06 0.06 0.06 1"/>
      </material>
    </visual>
    <collision>
      <origin xyz="0 0 0" rpy="0 0 0"/>
      <geometry>
        <box size="0.03 0.10 0.03"/>
      </geometry>
    </collision>
  </link>
  <joint name="joint7" type="prismatic">
    <origin xyz="0 0 0.13503" rpy="1.5708 0 1.5708"/>
    <parent link="link6"/>
    <child link="link7"/>
    <axis xyz="0 0 -1"/>
    <limit lower="0" upper="0.04" effort="10" velocity="1"/>
  </joint>

  <link name="link8">
    <inertial>
      <origin xyz="0.000277816920932317 0.0467673824063769 -0.00921030054508036" rpy="0 0 0"/>
      <mass value="0.0264822021416248"/>
      <inertia ixx="9.99779119357223E-06" ixy="-1.57542283433504E-07" ixz="2.71367446701359E-08" iyy="6.17952441557932E-06" iyz="1.58939319453383E-06" izz="1.4210192754512E-05"/>
    </inertial>
    <visual>
      <origin xyz="0 0 0" rpy="0 0 0"/>
      <geometry>
        <mesh filename="../meshes/dark_dae/link8.obj"/>
      </geometry>
      <material name="link8_color">
        <color rgba="0.06 0.06 0.06 1"/>
      </material>
    </visual>
    <collision>
      <origin xyz="0 0 0" rpy="0 0 0"/>
      <geometry>
        <box size="0.03 0.10 0.03"/>
      </geometry>
    </collision>
  </link>
  <joint name="joint8" type="prismatic">
    <origin xyz="0 0 0.13503" rpy="-1.5708 0 1.5708"/>
    <parent link="link6"/>
    <child link="link8"/>
    <axis xyz="0 0 1"/>
    <limit lower="-0.04" upper="0" effort="10" velocity="1"/>
  </joint>
</robot>
